Workbook

Sheet Cấu trúc nhóm
A1: CẤU TRÚC NHÓM
A2: Nhóm 8 – Web đặt lịch học gia sư online
A3: NO | B3: Name | C3: Account git | D3: Role | E3: Mã trong bảng | F3: Trọng tâm công việc
A4: 1 | B4: Nguyễn Ngọc Thiện | C4: thien0901 | D4: Product Owner | E4: SV1 | F4: PO + QA/Test
A5: 2 | B5: Nguyễn Hoàng Hải | C5: hhai0410 | D5: Scrum Master | E5: SV2 | F5: SM + DevOps/Tài liệu
A6: 3 | B6: Nguyễn Hữu Phượng | C6: huuphuong1911 | D6: Developer | E6: SV3 | F6: Backend (Controller/Service)
A7: 4 | B7: Nguyễn Tiến Thành | C7: [git-account-5] | D7: Developer | E7: SV4 | F7: Frontend (View/UI)
A8: 5 | B8: Nguyễn Đặng Nhân | C8: NhanNguyen-dotcom | D8: Developer | E8: SV5 | F8: CSDL + Backend/Job
A10: Ghi chú: điền họ tên và tài khoản Git vào các ô vàng; mã SV1–SV5 dùng ở cột Owner của mọi sheet.

Sheet Release planning
A1: Web đặt lịch học gia sư online – RELEASE PLAN
A2: Mỗi bản phát hành gồm các Sprint và User Story tương ứng
A3: Release no | B3: Feature name | C3: Sprint | D3: Priority | E3: Start date | F3: End date | G3: Status | H3: Goal
A4: V1.0 | B4: Tài khoản, hồ sơ gia sư, bảo mật nền tảng, duyệt hồ sơ, trang chi tiết gia sư | C4: Sprint #1 | D4: Cao | E4: ='Sprint planning'!B13 -> 46321 | F4: ='Sprint planning'!C13 -> 46339 | G4: To do | H4: ='Sprint Goal'!F5 -> Chúng ta tập trung vào gia sư đăng ký, đưa hồ sơ chuyên môn lên hệ thống và được admin kiểm duyệt để hồ sơ hiển thị công khai. Chúng ta tin điều này mang lại một kênh tự giới thiệu năng lực và sự tin cậy nhờ được kiểm duyệt cho gia sư và học viên. Điều này sẽ được xác nhận khi một gia sư thử nghiệm đăng ký, đăng nhập, điền xong hồ sơ; admin duyệt; rồi người chưa đăng nhập mở được trang chi tiết hồ sơ đã duyệt (hồ sơ chưa duyệt trả về 404).
A5: V1.0 | B5: Tìm kiếm/lọc, lịch rảnh, đặt lịch, gia sư xác nhận/từ chối | C5: Sprint #2 | D5: Cao | E5: ='Sprint planning'!B14 -> 46342 | F5: ='Sprint planning'!C14 -> 46360 | G5: To do | H5: ='Sprint Goal'!F6 -> Chúng ta tập trung vào học viên tìm đúng gia sư theo môn và học phí rồi đặt được buổi học vào khung giờ rảnh của gia sư, và gia sư xác nhận được yêu cầu. Chúng ta tin điều này mang lại lịch học chắc chắn, không trùng giờ và đỡ mất thời gian tìm gia sư cho học viên và gia sư. Điều này sẽ được xác nhận khi một học viên thử lọc theo môn và khoảng giá (≤ 2 giây với 500 hồ sơ mẫu) và đặt một khung giờ; hai học viên cùng đặt một khung giờ thì chỉ một người thành công; gia sư chấp nhận để booking thành "Đã xác nhận" (phát hành V1.0).
A6: V2.0 | B6: Thanh toán online (sandbox), phòng học video, kiểm thử tổng/UAT và triển khai | C6: Sprint #3 | D6: Cao | E6: ='Sprint planning'!B15 -> 46363 | F6: ='Sprint planning'!C15 -> 46381 | G6: To do | H6: ='Sprint Goal'!F7 -> Chúng ta tập trung vào học viên thanh toán online và vào học video ngay trên web, và bản V2.0 sẵn sàng cho người dùng thật. Chúng ta tin điều này mang lại khả năng giữ chỗ buổi học không cần tiền mặt và học không phải cài thêm phần mềm cho học viên và gia sư. Điều này sẽ được xác nhận khi ≥ 5 người dùng thử hoàn thành trọn luồng đăng ký → tìm → đặt → thanh toán → vào cùng phòng học đúng giờ trên bản chạy HTTPS .
A7: Mở rộng | B7: Hủy/đổi lịch (US10), nhắc lịch (US16), đánh giá gia sư (US15), lịch cá nhân (US11), lịch sử giao dịch & hoàn tiền tự động (US13), quản lý người dùng/môn học (US17), báo cáo thống kê (US18) | C7: — | D7: Thấp | G7: Backlog | H7: Chưa cam kết: chỉ làm khi còn năng lực sau Sprint 3 hoặc thay thế story bị cắt.

Sheet Story mapping
A1: STORY MAPPING
A3: Link bảng Miro: | B3: [dán link Miro của nhóm]
A5: Phát hành | B5: Tài khoản & hồ sơ | C5: Tìm gia sư | D5: Đặt lịch | E5: Thanh toán | F5: Học online | G5: Sau buổi học | H5: Quản trị & nền tảng
A6: V1.0 (Sprint 1–2) | B6: US01 · Đăng ký tài khoản (Sprint 1, 5 SP) US02 · Đăng nhập & đặt lại mật khẩu (Sprint 1, 5 SP) US03 · Tạo/cập nhật hồ sơ gia sư (Sprint 1, 8 SP) US04 · Duyệt hồ sơ gia sư (Sprint 1, 5 SP) | C6: US05 · Tìm kiếm & lọc gia sư (Sprint 2, 8 SP) US06 · Xem chi tiết gia sư (Sprint 1, 3 SP) | D6: US07 · Thiết lập lịch rảnh (Sprint 2, 8 SP) US08 · Đặt lịch buổi học (Sprint 2, 8 SP) US09 · Xác nhận/từ chối yêu cầu đặt lịch (Sprint 2, 5 SP) | H6: US19 · Bảo mật nền tảng (HTTPS, phân quyền) (Sprint 1, 5 SP)
A7: V2.0 (Sprint 3) | E7: US12 · Thanh toán online (Sprint 3, 13 SP) | F7: US14 · Phòng học video (Sprint 3, 8 SP) | H7: US20 · Kiểm thử, UAT & triển khai (Sprint 3, 8 SP)
A8: Mở rộng (chưa cam kết) | D8: US10 · Hủy/đổi lịch (Mở rộng, 5 SP) US11 · Xem lịch cá nhân (Mở rộng, 5 SP) | E8: US13 · Lịch sử giao dịch (Mở rộng, 5 SP) | G8: US15 · Đánh giá gia sư (Mở rộng, 3 SP) US16 · Thông báo & nhắc lịch (Mở rộng, 5 SP) | H8: US17 · Quản lý người dùng & môn học (Mở rộng, 5 SP) US18 · Báo cáo & thống kê (Mở rộng, 5 SP)
A10: Cột Quản trị & nền tảng gồm hai story kỹ thuật (US19, US20) – gắn PBI type "technical" ở Product Backlog.

Sheet Product Backlog
A1: WEB ĐẶT LỊCH HỌC GIA SƯ ONLINE – PRODUCT BACKLOG
A2: Tên dự án: Web đặt lịch học gia sư online · User Story theo mẫu "As a … I want … so that …" · Acceptance Criteria theo Given/When/Then
A3: Epic | B3: PBI type | C3: UID | D3: Product Backlog Item | E3: User type [as a] | F3: I WANT/NEED [do some task] | G3: SO THAT I CAN [get some results] | H3: Acceptance criteria | I3: Testing (kịch bản kiểm thử) | J3: Estimate (Story point) | K3: Estimated effort (giờ) | L3: Sprint | M3: Status | N3: Priority
A4: E1. Tài khoản & Phân quyền | B4: story | C4: US01 | D4: Đăng ký tài khoản | E4: học viên / gia sư | F4: đăng ký tài khoản bằng email và mật khẩu | G4: tôi có thể sử dụng hệ thống theo đúng vai trò của mình | H4: Given tôi ở trang đăng ký, When tôi nhập email chưa tồn tại + mật khẩu ≥ 8 ký tự và chọn vai trò, Then tài khoản được tạo và email xác nhận được gửi. Given email đã tồn tại, When tôi đăng ký, Then hiển thị lỗi "Email đã được sử dụng". Mật khẩu được băm (không lưu dạng rõ). | I4: TC01: đăng ký hợp lệ; TC02: trùng email; TC03: mật khẩu yếu; TC04: email sai định dạng; TC05: kiểm tra mật khẩu đã băm trong DB. | J4: 5 | K4: =J4*'Sprint planning'!$B$3 -> 20 | L4: 1 | M4: To do | N4: Cao
A5: E1. Tài khoản & Phân quyền | B5: story | C5: US02 | D5: Đăng nhập & đặt lại mật khẩu | E5: người dùng | F5: đăng nhập, đăng xuất và đặt lại mật khẩu khi quên | G5: tôi truy cập được tài khoản an toàn và lấy lại quyền truy cập khi quên mật khẩu | H5: Given thông tin đúng, When đăng nhập, Then vào trang chủ theo vai trò. Sai mật khẩu 5 lần liên tiếp thì khóa 15 phút. Liên kết đặt lại mật khẩu hết hạn sau 30 phút và dùng được một lần. | I5: TC01: đăng nhập đúng/sai; TC02: khóa sau 5 lần sai; TC03: đăng xuất hủy phiên; TC04: token đặt lại hết hạn; TC05: dùng lại token. | J5: 5 | K5: =J5*'Sprint planning'!$B$3 -> 20 | L5: 1 | M5: To do | N5: Cao
A6: E1. Tài khoản & Phân quyền | B6: story | C6: US03 | D6: Tạo/cập nhật hồ sơ gia sư | E6: gia sư | F6: cập nhật hồ sơ (ảnh, giới thiệu, môn dạy, học phí/giờ, kinh nghiệm, chứng chỉ) | G6: học viên hiểu rõ năng lực của tôi và chọn tôi | H6: Given tôi là gia sư đã đăng nhập, When tôi điền đủ trường bắt buộc và lưu, Then hồ sơ có trạng thái "Chờ duyệt". Ảnh/chứng chỉ chỉ nhận JPG/PNG/PDF ≤ 5 MB. Học phí là số dương. | I6: TC01: lưu hồ sơ hợp lệ; TC02: thiếu trường bắt buộc; TC03: upload sai định dạng/quá dung lượng; TC04: học phí âm; TC05: sửa hồ sơ đã duyệt → quay về chờ duyệt. | J6: 8 | K6: =J6*'Sprint planning'!$B$3 -> 32 | L6: 1 | M6: To do | N6: Cao
A7: E8. Phi chức năng & Triển khai | B7: technical | C7: US19 | D7: Bảo mật nền tảng (HTTPS, phân quyền) | E7: người dùng | F7: dữ liệu của tôi được bảo vệ bằng HTTPS, phân quyền và chống các tấn công phổ biến | G7: thông tin cá nhân và giao dịch không bị lộ hoặc bị giả mạo | H7: Toàn bộ trang chạy HTTPS (có HSTS). Truy cập trái vai trò trả về 403. Form có anti-forgery token; dữ liệu xuất ra được mã hóa HTML; truy vấn dùng tham số (EF Core). | I7: TC01: truy cập HTTP bị chuyển HTTPS; TC02: Student vào trang Admin → 403; TC03: gửi form thiếu CSRF token → 400; TC04: chèn <script> không thực thi; TC05: thử SQL injection ở ô tìm kiếm. | J7: 5 | K7: =J7*'Sprint planning'!$B$3 -> 20 | L7: 1 | M7: To do | N7: Cao
A8: E1. Tài khoản & Phân quyền | B8: story | C8: US04 | D8: Duyệt hồ sơ gia sư | E8: quản trị viên | F8: xem danh sách hồ sơ gia sư chờ duyệt và duyệt hoặc từ chối kèm lý do | G8: chỉ gia sư đạt chuẩn mới hiển thị với học viên | H8: Given có hồ sơ "Chờ duyệt", When admin duyệt, Then trạng thái thành "Đã duyệt" và gia sư nhận email. Từ chối bắt buộc nhập lý do. Chỉ hồ sơ "Đã duyệt" xuất hiện ở trang tìm kiếm. | I8: TC01: duyệt hồ sơ; TC02: từ chối không nhập lý do; TC03: email kết quả; TC04: hồ sơ chưa duyệt không hiện ở tìm kiếm. | J8: 5 | K8: =J8*'Sprint planning'!$B$3 -> 20 | L8: 1 | M8: To do | N8: Cao
A9: E2. Tìm kiếm gia sư | B9: story | C9: US06 | D9: Xem chi tiết gia sư | E9: học viên | F9: xem trang chi tiết hồ sơ gia sư (giới thiệu, học phí, đánh giá, lịch rảnh tóm tắt) | G9: tôi đánh giá được gia sư trước khi đặt lịch | H9: Trang hiển thị đủ thông tin hồ sơ đã duyệt. Có nút "Đặt lịch" dẫn tới chọn khung giờ. Hồ sơ không tồn tại hoặc chưa duyệt → trang 404. | I9: TC01: hiển thị đúng dữ liệu; TC02: nút Đặt lịch; TC03: truy cập ID không hợp lệ. | J9: 3 | K9: =J9*'Sprint planning'!$B$3 -> 12 | L9: 1 | M9: To do | N9: Trung bình
A10: E2. Tìm kiếm gia sư | B10: story | C10: US05 | D10: Tìm kiếm & lọc gia sư | E10: học viên | F10: tìm kiếm gia sư theo môn học, mức học phí, điểm đánh giá, ngôn ngữ giảng dạy | G10: tôi nhanh chóng chọn được gia sư phù hợp nhu cầu và ngân sách | H10: Given có ≥ 1 gia sư đã duyệt, When tôi lọc theo môn + khoảng giá, Then danh sách chỉ gồm gia sư thỏa cả hai điều kiện. Kết quả phân trang 10 gia sư/trang, sắp xếp được theo giá/đánh giá. Thời gian phản hồi ≤ 2 giây với 500 hồ sơ. | I10: TC01: lọc theo môn; TC02: lọc kết hợp; TC03: không có kết quả → thông báo; TC04: phân trang; TC05: hiệu năng 500 hồ sơ. | J10: 8 | K10: =J10*'Sprint planning'!$B$3 -> 32 | L10: 2 | M10: To do | N10: Cao
A11: E3. Lịch & Đặt lịch | B11: story | C11: US07 | D11: Thiết lập lịch rảnh | E11: gia sư | F11: thiết lập các khung giờ rảnh theo tuần | G11: học viên chỉ đặt vào thời điểm tôi có thể dạy | H11: Given tôi là gia sư đã duyệt, When tôi thêm khung giờ, Then khung giờ hiển thị trên lịch tuần. Không cho phép hai khung giờ chồng lấn. Không xóa/sửa được khung giờ đã có người đặt. | I11: TC01: thêm khung giờ; TC02: chồng lấn bị chặn; TC03: sửa/xóa khung đã đặt bị chặn; TC04: khung giờ trong quá khứ bị chặn. | J11: 8 | K11: =J11*'Sprint planning'!$B$3 -> 32 | L11: 2 | M11: To do | N11: Cao
A12: E3. Lịch & Đặt lịch | B12: story | C12: US08 | D12: Đặt lịch buổi học | E12: học viên | F12: xác nhận đặt buổi học theo khung giờ | G12: tôi có buổi học đúng thời điểm mình mong muốn | H12: Given khung giờ còn trống, When tôi xác nhận, Then tạo booking trạng thái "Chờ xác nhận" và gửi thông báo cho gia sư. Hai học viên đặt cùng khung giờ cùng lúc: chỉ một người thành công. Không đặt được khung giờ đã qua. | I12: TC01: đặt thành công; TC02: đặt đồng thời (2 người); TC03: khung giờ đã qua; TC04: chưa đăng nhập bị chuyển về đăng nhập. | J12: 8 | K12: =J12*'Sprint planning'!$B$3 -> 32 | L12: 2 | M12: To do | N12: Cao
A13: E3. Lịch & Đặt lịch | B13: story | C13: US09 | D13: Xác nhận/từ chối yêu cầu đặt lịch | E13: gia sư | F13: chấp nhận hoặc từ chối yêu cầu đặt lịch của học viên | G13: tôi chủ động sắp xếp lịch dạy của mình | H13: Chấp nhận → booking "Đã xác nhận"; từ chối → khung giờ được mở lại. Yêu cầu không phản hồi sau 24 giờ tự động hủy. Học viên nhận thông báo kết quả. | I13: TC01: chấp nhận; TC02: từ chối mở lại slot; TC03: tự hủy sau 24 giờ; TC04: thông báo cho học viên. | J13: 5 | K13: =J13*'Sprint planning'!$B$3 -> 20 | L13: 2 | M13: To do | N13: Cao
A14: E4. Thanh toán | B14: story | C14: US12 | D14: Thanh toán online | E14: học viên | F14: thanh toán học phí online khi đặt lịch | G14: tôi giữ chỗ buổi học và không phải trả tiền mặt | H14: Given booking đã được gia sư xác nhận, When tôi thanh toán thành công, Then booking chuyển "Đã thanh toán" và có biên lai. Thất bại/hết hạn → booking giữ nguyên, cho phép thử lại. Không lưu số thẻ; callback được xác thực chữ ký; mỗi giao dịch xử lý đúng một lần. | I14: TC01: thanh toán thành công; TC02: thất bại/hủy giữa chừng; TC03: callback giả mạo bị từ chối; TC04: callback trùng lặp; TC05: hết thời gian chờ. | J14: 13 | K14: =J14*'Sprint planning'!$B$3 -> 52 | L14: 3 | M14: To do | N14: Cao
A15: E5. Học trực tuyến | B15: story | C15: US14 | D15: Phòng học video | E15: học viên / gia sư | F15: vào phòng học video riêng của buổi học bằng một nút bấm | G15: chúng tôi học trực tuyến mà không cần cài thêm phần mềm | H15: Mỗi booking đã thanh toán có một phòng học duy nhất. Chỉ học viên và gia sư của booking vào được, trong khoảng 10 phút trước đến hết giờ học. Sau buổi học, booking chuyển "Hoàn thành". | I15: TC01: vào phòng đúng giờ; TC02: người ngoài truy cập bị chặn; TC03: vào sớm hơn 10 phút bị chặn; TC04: chạy trên Chrome/Edge/Firefox. | J15: 8 | K15: =J15*'Sprint planning'!$B$3 -> 32 | L15: 3 | M15: To do | N15: Cao
A16: E8. Phi chức năng & Triển khai | B16: technical | C16: US20 | D16: Kiểm thử, UAT & triển khai | E16: nhóm phát triển | F16: kiểm thử tích hợp/hồi quy, UAT, triển khai và hoàn thiện tài liệu hướng dẫn | G16: sản phẩm ổn định, đáp ứng Definition of Done và sẵn sàng bàn giao | H16: Không còn lỗi mức Critical/High; 100% user story đạt tiêu chí chấp nhận. UAT với ≥ 5 người dùng thử và có biên bản phản hồi. Triển khai chạy HTTPS; có hướng dẫn sử dụng. | I16: TC: bộ hồi quy các luồng chính (đăng ký → tìm → đặt → thanh toán → học → đánh giá); UAT checklist. | J16: 8 | K16: =J16*'Sprint planning'!$B$3 -> 32 | L16: 3 | M16: To do | N16: Cao
A17: E3. Lịch & Đặt lịch | B17: story | C17: US10 | D17: Hủy/đổi lịch | E17: học viên | F17: hủy hoặc đổi lịch buổi học trước giờ học theo quy định | G17: tôi linh hoạt khi có việc đột xuất mà vẫn công bằng với gia sư | H17: Hủy/đổi được khi còn ≥ 12 giờ trước giờ học. Sau mốc 12 giờ hệ thống từ chối và hiển thị quy định. Khung giờ cũ được mở lại sau khi hủy/đổi. Booking đã thanh toán khi hủy đúng quy định chuyển trạng thái "Chờ hoàn tiền" để admin xử lý thủ công (tự động hóa ở US13 – backlog mở rộng). | I17: TC01: hủy trước 12 giờ; TC02: hủy sau mốc 12 giờ; TC03: đổi sang slot khác; TC04: slot cũ được mở lại; TC05: hủy booking đã thanh toán → Chờ hoàn tiền. | J17: 5 | K17: =J17*'Sprint planning'!$B$3 -> 20 | L17: Mở rộng | M17: Backlog | N17: Trung bình
A18: E3. Lịch & Đặt lịch | B18: story | C18: US11 | D18: Xem lịch cá nhân | E18: học viên / gia sư | F18: xem lịch các buổi học của mình dạng lịch tuần/tháng | G18: tôi nắm được các buổi sắp tới | H18: Lịch hiển thị đủ buổi theo trạng thái (chờ/xác nhận/hoàn thành/hủy) bằng màu khác nhau. Chỉ xem được lịch của chính mình. Bấm vào buổi học xem được chi tiết. | I18: TC01: hiển thị đúng buổi học; TC02: lọc theo trạng thái; TC03: không xem được lịch người khác. | J18: 5 | K18: =J18*'Sprint planning'!$B$3 -> 20 | L18: Mở rộng | M18: Backlog | N18: Trung bình
A19: E4. Thanh toán | B19: story | C19: US13 | D19: Lịch sử giao dịch & hoàn tiền | E19: học viên | F19: xem lịch sử giao dịch và được hoàn tiền khi hủy đúng quy định | G19: tôi kiểm soát chi tiêu và yên tâm khi phải hủy | H19: Hủy trước 12 giờ → hoàn 100%; sau mốc → không hoàn. Lịch sử hiển thị mã giao dịch, số tiền, trạng thái, thời gian. Hoàn tiền ghi nhận một lần cho mỗi booking. | I19: TC01: hoàn 100%; TC02: không hoàn sau mốc; TC03: hoàn tiền trùng lặp bị chặn; TC04: hiển thị lịch sử. | J19: 5 | K19: =J19*'Sprint planning'!$B$3 -> 20 | L19: Mở rộng | M19: Backlog | N19: Trung bình
A20: E6. Đánh giá & Thông báo | B20: story | C20: US15 | D20: Đánh giá gia sư | E20: học viên | F20: đánh giá (1–5 sao) và nhận xét gia sư sau buổi học | G20: những học viên khác có thêm thông tin tham khảo | H20: Chỉ đánh giá được buổi học "Hoàn thành" và mỗi buổi một lần. Điểm trung bình của gia sư được cập nhật ngay. Nhận xét tối đa 500 ký tự. | I20: TC01: đánh giá hợp lệ; TC02: đánh giá buổi chưa hoàn thành; TC03: đánh giá lần hai; TC04: cập nhật điểm TB. | J20: 3 | K20: =J20*'Sprint planning'!$B$3 -> 12 | L20: Mở rộng | M20: Backlog | N20: Trung bình
A21: E6. Đánh giá & Thông báo | B21: story | C21: US16 | D21: Thông báo & nhắc lịch | E21: người dùng | F21: nhận email và thông báo trong web về trạng thái đặt lịch và nhắc lịch trước 24 giờ/1 giờ | G21: tôi không bỏ lỡ buổi học | H21: Có email cho: đặt lịch, xác nhận/từ chối, hủy, thanh toán. Nhắc lịch gửi đúng mốc 24 giờ và 1 giờ. Chuông thông báo hiển thị số chưa đọc và đánh dấu đã đọc được. | I21: TC01: email từng sự kiện; TC02: nhắc 24 giờ/1 giờ; TC03: đánh dấu đã đọc; TC04: không gửi nhắc cho buổi đã hủy. | J21: 5 | K21: =J21*'Sprint planning'!$B$3 -> 20 | L21: Mở rộng | M21: Backlog | N21: Trung bình
A22: E7. Quản trị hệ thống | B22: story | C22: US17 | D22: Quản lý người dùng & môn học | E22: quản trị viên | F22: quản lý người dùng (khóa/mở khóa) và danh mục môn học | G22: hệ thống luôn sạch dữ liệu và an toàn | H22: Khóa tài khoản thì người đó không đăng nhập được. Thêm/sửa/xóa môn học; không xóa môn đang được gia sư sử dụng. Mọi thao tác quản trị có ghi log. | I22: TC01: khóa/mở khóa; TC02: xóa môn đang dùng bị chặn; TC03: ghi log thao tác. | J22: 5 | K22: =J22*'Sprint planning'!$B$3 -> 20 | L22: Mở rộng | M22: Backlog | N22: Trung bình
A23: E7. Quản trị hệ thống | B23: story | C23: US18 | D23: Báo cáo & thống kê | E23: quản trị viên | F23: xem báo cáo doanh thu và số buổi học theo ngày/tháng và xuất ra Excel | G23: tôi theo dõi hiệu quả hoạt động của nền tảng | H23: Dashboard có biểu đồ doanh thu và số buổi theo thời gian chọn. Số liệu khớp với dữ liệu giao dịch. Xuất được file .xlsx/.csv. | I23: TC01: số liệu khớp giao dịch; TC02: lọc theo khoảng ngày; TC03: xuất file mở được. | J23: 5 | K23: =J23*'Sprint planning'!$B$3 -> 20 | L23: Mở rộng | M23: Backlog | N23: Thấp
I24: Tổng | J24: =SUM(J4:J23) -> 122 | K24: =SUM(K4:K23) -> 488
I25: Đã cam kết (Sprint 1–3) | J25: =SUMIF(L4:L23,">=1",J4:J23) -> 89 | K25: =SUMIF(L4:L23,">=1",K4:K23) -> 356
A27: Story Point là đề xuất ban đầu (dãy Fibonacci); nhóm 5 người ước lượng lại bằng Planning Poker rồi sửa cột J. 1 SP = 4 giờ công là giả định (chỉnh ở 'Sprint planning'!B3). Sprint "Mở rộng" = chưa cam kết.

Sheet Sprint planning
A1: SPRINT PLANNING
A2: Mục tiêu: xác định rõ công việc trong Sprint, ước lượng công việc và xác định Sprint Goal (PO đề xuất, Dev Team cam kết theo năng lực ròng)
A3: Quy đổi: số giờ / 1 Story Point | B3: 4
A4: Số thành viên | B4: 5
A5: Giờ làm việc / người / tuần | B5: 12
A6: Số tuần / Sprint | B6: 3
A7: Giờ họp Scrum / người / Sprint | B7: 8.25
A8: Ngày nghỉ lễ trong thời gian dự án | B8: 46388
A9: Năng lực ròng mỗi Sprint (giờ) | B9: =B4*(B5*B6-B7) -> 138.75 | C9: Công thức: thành viên × (giờ/tuần × số tuần − giờ họp Scrum)
A11: Bảng tổng hợp Sprint (Sprint Goal viết theo mẫu Scrum.org ở sheet 'Sprint Goal')
A12: Sprint | B12: Bắt đầu | C12: Kết thúc | D12: Số ngày làm việc | E12: Sprint Goal | F12: Release | G12: User Story được chọn | H12: Tổng SP | I12: Ước lượng (giờ) | J12: % năng lực ròng | K12: Giờ task (US_Task)
A13: Sprint 1 | B13: 46321 | C13: 46339 | D13: =NETWORKDAYS(B13,C13,$B$8) -> 15 | E13: ='Sprint Goal'!F5 -> Chúng ta tập trung vào gia sư đăng ký, đưa hồ sơ chuyên môn lên hệ thống và được admin kiểm duyệt để hồ sơ hiển thị công khai. Chúng ta tin điều này mang lại một kênh tự giới thiệu năng lực và sự tin cậy nhờ được kiểm duyệt cho gia sư và học viên. Điều này sẽ được xác nhận khi một gia sư thử nghiệm đăng ký, đăng nhập, điền xong hồ sơ; admin duyệt; rồi người chưa đăng nhập mở được trang chi tiết hồ sơ đã duyệt (hồ sơ chưa duyệt trả về 404). | F13: V1.0 | G13: US01 – Đăng ký tài khoản (5 SP) US02 – Đăng nhập & đặt lại mật khẩu (5 SP) US03 – Tạo/cập nhật hồ sơ gia sư (8 SP) US19 – Bảo mật nền tảng (HTTPS, phân quyền) (5 SP) US04 – Duyệt hồ sơ gia sư (5 SP) US06 – Xem chi tiết gia sư (3 SP) | H13: =SUMIF('Product Backlog'!$L$4:$L$23,1,'Product Backlog'!$J$4:$J$23) -> 31 | I13: =H13*$B$3 -> 124 | J13: =I13/$B$9 -> 0.89369369 | K13: =SUMIF(US_Task!$H:$H,1,US_Task!$F:$F) -> 124
A14: Sprint 2 | B14: 46342 | C14: 46360 | D14: =NETWORKDAYS(B14,C14,$B$8) -> 15 | E14: ='Sprint Goal'!F6 -> Chúng ta tập trung vào học viên tìm đúng gia sư theo môn và học phí rồi đặt được buổi học vào khung giờ rảnh của gia sư, và gia sư xác nhận được yêu cầu. Chúng ta tin điều này mang lại lịch học chắc chắn, không trùng giờ và đỡ mất thời gian tìm gia sư cho học viên và gia sư. Điều này sẽ được xác nhận khi một học viên thử lọc theo môn và khoảng giá (≤ 2 giây với 500 hồ sơ mẫu) và đặt một khung giờ; hai học viên cùng đặt một khung giờ thì chỉ một người thành công; gia sư chấp nhận để booking thành "Đã xác nhận" (phát hành V1.0). | F14: V1.0 | G14: US05 – Tìm kiếm & lọc gia sư (8 SP) US07 – Thiết lập lịch rảnh (8 SP) US08 – Đặt lịch buổi học (8 SP) US09 – Xác nhận/từ chối yêu cầu đặt lịch (5 SP) | H14: =SUMIF('Product Backlog'!$L$4:$L$23,2,'Product Backlog'!$J$4:$J$23) -> 29 | I14: =H14*$B$3 -> 116 | J14: =I14/$B$9 -> 0.83603604 | K14: =SUMIF(US_Task!$H:$H,2,US_Task!$F:$F) -> 116
A15: Sprint 3 | B15: 46363 | C15: 46381 | D15: =NETWORKDAYS(B15,C15,$B$8) -> 15 | E15: ='Sprint Goal'!F7 -> Chúng ta tập trung vào học viên thanh toán online và vào học video ngay trên web, và bản V2.0 sẵn sàng cho người dùng thật. Chúng ta tin điều này mang lại khả năng giữ chỗ buổi học không cần tiền mặt và học không phải cài thêm phần mềm cho học viên và gia sư. Điều này sẽ được xác nhận khi ≥ 5 người dùng thử hoàn thành trọn luồng đăng ký → tìm → đặt → thanh toán → vào cùng phòng học đúng giờ trên bản chạy HTTPS . | F15: V2.0 | G15: US12 – Thanh toán online (13 SP) US14 – Phòng học video (8 SP) US20 – Kiểm thử, UAT & triển khai (8 SP) | H15: =SUMIF('Product Backlog'!$L$4:$L$23,3,'Product Backlog'!$J$4:$J$23) -> 29 | I15: =H15*$B$3 -> 116 | J15: =I15/$B$9 -> 0.83603604 | K15: =SUMIF(US_Task!$H:$H,3,US_Task!$F:$F) -> 116
G16: Tổng / kiểm tra | H16: =SUM(H13:H15) -> 89 | I16: =SUM(I13:I15) -> 356 | J16: =I16/(B9*3) -> 0.85525526 | K16: =IF(SUM(K13:K15)=I16,"OK: giờ task khớp Story Point","LỆCH: kiểm tra US_Task") -> OK: giờ task khớp Story Point
A18: Các bước họp Sprint Planning
A19: 1. PO nêu mục tiêu: "Nếu chỉ giao được MỘT kết quả trong Sprint này, đó là gì?" rồi chốt Sprint Goal (xem sheet 'Sprint Goal').
A20: 2. Dev Team ước lượng bằng Planning Poker, đối chiếu với năng lực ròng (B9) và chọn story cam kết (nên ≤ 90% năng lực).
A21: 3. Chia story thành Task và Subtask, ước lượng giờ, phân công Owner (xem 'Sprint backlog n').
A22: 4. Chốt ngày bắt đầu/kết thúc, phần có thể giảm/hoãn nếu trễ và giải pháp cho vấn đề chung của Sprint.

Sheet Sprint Goal
A1: e
A4: Sprint | B4: Our focus is on… | C4: We believe it delivers… | D4: …to | E4: This will be confirmed when… | F4: Sprint Goal hoàn chỉnh | G4: Story hỗ trợ Sprint Goal | H4: Phần có thể giảm/hoãn nếu trễ
A5: Sprint 1 | B5: gia sư đăng ký, đưa hồ sơ chuyên môn lên hệ thống và được admin kiểm duyệt để hồ sơ hiển thị công khai | C5: một kênh tự giới thiệu năng lực và sự tin cậy nhờ được kiểm duyệt | D5: gia sư và học viên | E5: một gia sư thử nghiệm đăng ký, đăng nhập, điền xong hồ sơ; admin duyệt; rồi người chưa đăng nhập mở được trang chi tiết hồ sơ đã duyệt (hồ sơ chưa duyệt trả về 404) | F5: ="Chúng ta tập trung vào "&B5&". Chúng ta tin điều này mang lại "&C5&" cho "&D5&". Điều này sẽ được xác nhận khi "&E5&"." -> Chúng ta tập trung vào gia sư đăng ký, đưa hồ sơ chuyên môn lên hệ thống và được admin kiểm duyệt để hồ sơ hiển thị công khai. Chúng ta tin điều này mang lại một kênh tự giới thiệu năng lực và sự tin cậy nhờ được kiểm duyệt cho gia sư và học viên. Điều này sẽ được xác nhận khi một gia sư thử nghiệm đăng ký, đăng nhập, điền xong hồ sơ; admin duyệt; rồi người chưa đăng nhập mở được trang chi tiết hồ sơ đã duyệt (hồ sơ chưa duyệt trả về 404). | G5: US01 – Đăng ký tài khoản US02 – Đăng nhập & đặt lại mật khẩu US03 – Tạo/cập nhật hồ sơ gia sư US19 – Bảo mật nền tảng (HTTPS, phân quyền) US04 – Duyệt hồ sơ gia sư US06 – Xem chi tiết gia sư | H5: Đặt lại mật khẩu (T02.2) có thể lùi sang Sprint 2 nếu trễ.
A6: Sprint 2 | B6: học viên tìm đúng gia sư theo môn và học phí rồi đặt được buổi học vào khung giờ rảnh của gia sư, và gia sư xác nhận được yêu cầu | C6: lịch học chắc chắn, không trùng giờ và đỡ mất thời gian tìm gia sư | D6: học viên và gia sư | E6: một học viên thử lọc theo môn và khoảng giá (≤ 2 giây với 500 hồ sơ mẫu) và đặt một khung giờ; hai học viên cùng đặt một khung giờ thì chỉ một người thành công; gia sư chấp nhận để booking thành "Đã xác nhận" (phát hành V1.0) | F6: ="Chúng ta tập trung vào "&B6&". Chúng ta tin điều này mang lại "&C6&" cho "&D6&". Điều này sẽ được xác nhận khi "&E6&"." -> Chúng ta tập trung vào học viên tìm đúng gia sư theo môn và học phí rồi đặt được buổi học vào khung giờ rảnh của gia sư, và gia sư xác nhận được yêu cầu. Chúng ta tin điều này mang lại lịch học chắc chắn, không trùng giờ và đỡ mất thời gian tìm gia sư cho học viên và gia sư. Điều này sẽ được xác nhận khi một học viên thử lọc theo môn và khoảng giá (≤ 2 giây với 500 hồ sơ mẫu) và đặt một khung giờ; hai học viên cùng đặt một khung giờ thì chỉ một người thành công; gia sư chấp nhận để booking thành "Đã xác nhận" (phát hành V1.0). | G6: US05 – Tìm kiếm & lọc gia sư US07 – Thiết lập lịch rảnh US08 – Đặt lịch buổi học US09 – Xác nhận/từ chối yêu cầu đặt lịch | H6: Gợi ý từ khóa (T05.4) và tự hủy yêu cầu quá 24 giờ (T09.3) có thể bỏ nếu trễ.
A7: Sprint 3 | B7: học viên thanh toán online và vào học video ngay trên web, và bản V2.0 sẵn sàng cho người dùng thật | C7: khả năng giữ chỗ buổi học không cần tiền mặt và học không phải cài thêm phần mềm | D7: học viên và gia sư | E7: ≥ 5 người dùng thử hoàn thành trọn luồng đăng ký → tìm → đặt → thanh toán → vào cùng phòng học đúng giờ trên bản chạy HTTPS | F7: ="Chúng ta tập trung vào "&B7&". Chúng ta tin điều này mang lại "&C7&" cho "&D7&". Điều này sẽ được xác nhận khi "&E7&"." -> Chúng ta tập trung vào học viên thanh toán online và vào học video ngay trên web, và bản V2.0 sẵn sàng cho người dùng thật. Chúng ta tin điều này mang lại khả năng giữ chỗ buổi học không cần tiền mặt và học không phải cài thêm phần mềm cho học viên và gia sư. Điều này sẽ được xác nhận khi ≥ 5 người dùng thử hoàn thành trọn luồng đăng ký → tìm → đặt → thanh toán → vào cùng phòng học đúng giờ trên bản chạy HTTPS . | G7: US12 – Thanh toán online US14 – Phòng học video US20 – Kiểm thử, UAT & triển khai | H7: Đồng hồ đếm giờ trong phòng học (một subtask của T14.4) và xử lý timeout nâng cao (T12.6, giữ phần cơ bản) có thể giảm nếu trễ.

Sheet Sprint backlog 1
A1: Sprint backlog 1
A2: Sprint Goal | B2: ='Sprint planning'!E13 -> Chúng ta tập trung vào gia sư đăng ký, đưa hồ sơ chuyên môn lên hệ thống và được admin kiểm duyệt để hồ sơ hiển thị công khai. Chúng ta tin điều này mang lại một kênh tự giới thiệu năng lực và sự tin cậy nhờ được kiểm duyệt cho gia sư và học viên. Điều này sẽ được xác nhận khi một gia sư thử nghiệm đăng ký, đăng nhập, điền xong hồ sơ; admin duyệt; rồi người chưa đăng nhập mở được trang chi tiết hồ sơ đã duyệt (hồ sơ chưa duyệt trả về 404).
J3: Effort còn lại cuối mỗi ngày (giờ) – nhập hằng ngày
A4: UID | B4: User story (Product Backlog Item) | C4: Task ID | D4: Sprint task | E4: Subtask | F4: Owner | G4: Status | H4: Estimated effort (giờ) | I4: Actual (giờ) | J4: Day 1 | K4: Day 2 | L4: Day 3 | M4: Day 4 | N4: Day 5 | O4: Day 6 | P4: Day 7 | Q4: Day 8 | R4: Day 9 | S4: Day 10 | T4: Day 11 | U4: Day 12 | V4: Day 13 | W4: Day 14 | X4: Day 15
I5: Ngày | J5: =WORKDAY(#REF!,0,'Sprint planning'!$B$8) -> #REF! | K5: =WORKDAY(#REF!,1,'Sprint planning'!$B$8) -> #REF! | L5: =WORKDAY(#REF!,2,'Sprint planning'!$B$8) -> #REF! | M5: =WORKDAY(#REF!,3,'Sprint planning'!$B$8) -> #REF! | N5: =WORKDAY(#REF!,4,'Sprint planning'!$B$8) -> #REF! | O5: =WORKDAY(#REF!,5,'Sprint planning'!$B$8) -> #REF! | P5: =WORKDAY(#REF!,6,'Sprint planning'!$B$8) -> #REF! | Q5: =WORKDAY(#REF!,7,'Sprint planning'!$B$8) -> #REF! | R5: =WORKDAY(#REF!,8,'Sprint planning'!$B$8) -> #REF! | S5: =WORKDAY(#REF!,9,'Sprint planning'!$B$8) -> #REF! | T5: =WORKDAY(#REF!,10,'Sprint planning'!$B$8) -> #REF! | U5: =WORKDAY(#REF!,11,'Sprint planning'!$B$8) -> #REF! | V5: =WORKDAY(#REF!,12,'Sprint planning'!$B$8) -> #REF! | W5: =WORKDAY(#REF!,13,'Sprint planning'!$B$8) -> #REF! | X5: =WORKDAY(#REF!,14,'Sprint planning'!$B$8) -> #REF!
A6: US01 (5 SP) | B6: Là học viên / gia sư, tôi muốn đăng ký tài khoản bằng email và mật khẩu để tôi có thể sử dụng hệ thống theo đúng vai trò của mình. | C6: T01.1 | D6: Thiết kế CSDL người dùng | E6: • Vẽ ERD Users–Roles • Tạo entity + migration EF Core • Seed 3 vai trò Student/Tutor/Admin | F6: SV5 | G6: To do | H6: 3
C7: T01.2 | D7: Xử lý đăng ký (Controller/Service) | E7: • Validate dữ liệu (email, mật khẩu) • Băm mật khẩu bằng ASP.NET Core Identity • Cấu hình dịch vụ email SMTP dùng chung + gửi email xác nhận | F7: SV1 | G7: To do | H7: 6
C8: T01.3 | D8: Giao diện đăng ký | E8: • Dựng form Razor + Bootstrap • Hiển thị lỗi validate • Responsive mobile | F8: SV4 | G8: To do | H8: 6
C9: T01.4 | D9: Kiểm thử đăng ký | E9: • Viết test case • Test trùng email / mật khẩu yếu | F9: SV1 | G9: To do | H9: 3
C10: T01.5 | D10: Review code & merge | E10: • Review pull request • Merge và kiểm tra build | F10: SV2 | G10: To do | H10: 2
A11: US02 (5 SP) | B11: Là người dùng, tôi muốn đăng nhập, đăng xuất và đặt lại mật khẩu khi quên để tôi truy cập được tài khoản an toàn và lấy lại quyền truy cập khi quên mật khẩu. | C11: T02.1 | D11: Đăng nhập / đăng xuất | E11: • Action đăng nhập • Khóa 15 phút sau 5 lần sai • Action đăng xuất | F11: SV3 | G11: To do | H11: 6
C12: T02.2 | D12: Quên / đặt lại mật khẩu | E12: • Sinh token có hạn 30 phút • Gửi email đặt lại • Trang đặt lại mật khẩu | F12: SV3 | G12: To do | H12: 5
C13: T02.3 | D13: Giao diện đăng nhập & quên mật khẩu | E13: • Trang đăng nhập • Trang quên/đặt lại mật khẩu • Thông báo lỗi/thành công | F13: SV4 | G13: To do | H13: 5
C14: T02.4 | D14: Kiểm thử đăng nhập | E14: • Test đăng nhập đúng/sai • Test token hết hạn/dùng lại | F14: SV1 | G14: To do | H14: 2
C15: T02.5 | D15: Review code & merge | E15: • Review pull request • Merge vào develop | F15: SV2 | G15: To do | H15: 2
A16: US03 (8 SP) | B16: Là gia sư, tôi muốn tạo và cập nhật hồ sơ (ảnh, giới thiệu, môn dạy, học phí/giờ, kinh nghiệm, chứng chỉ) để học viên hiểu rõ năng lực của tôi và chọn tôi. | C16: T03.1 | D16: Thiết kế CSDL hồ sơ gia sư | E16: • Vẽ ERD hồ sơ • Entity + migration • Seed danh sách môn học | F16: SV5 | G16: To do | H16: 5
C17: T03.2 | D17: CRUD hồ sơ gia sư | E17: • Action Create/Edit • Validate học phí, trường bắt buộc • Chuyển trạng thái Chờ duyệt khi lưu | F17: SV2 | G17: To do | H17: 8
C18: T03.3 | D18: Upload ảnh và chứng chỉ | E18: • Giới hạn định dạng JPG/PNG/PDF • Giới hạn 5 MB, đổi tên file ngẫu nhiên • Lưu ngoài thư mục wwwroot công khai (chứng chỉ) | F18: SV5 | G18: To do | H18: 5
C19: T03.4 | D19: Giao diện form hồ sơ nhiều bước | E19: • Dựng stepper • Kiểm tra dữ liệu phía client • Xem trước ảnh đại diện | F19: SV2 | G19: To do | H19: 8
C20: T03.5 | D20: Trang xem hồ sơ cá nhân | E20: • Dựng trang xem • Hiển thị trạng thái duyệt | F20: SV4 | G20: To do | H20: 3
C21: T03.6 | D21: Kiểm thử hồ sơ gia sư | E21: • Test upload sai định dạng/dung lượng • Test sửa hồ sơ đã duyệt | F21: SV1 | G21: To do | H21: 3
A22: US19 (5 SP) | B22: Là người dùng, tôi muốn dữ liệu của tôi được bảo vệ bằng HTTPS, phân quyền và chống các tấn công phổ biến để thông tin cá nhân và giao dịch không bị lộ hoặc bị giả mạo. | C22: T19.1 | D22: Thiết lập repo Git, quy ước nhánh, bảng công việc | E22: • Tạo repo, nhánh main/develop/feature • Quy ước commit + PR • Tạo board Scrum (Trello/Jira) | F22: SV2 | G22: To do | H22: 3
C23: T19.2 | D23: Cấu hình HTTPS/HSTS | E23: • Chứng chỉ phát triển Kestrel • Bắt buộc chuyển hướng HTTPS • Bật HSTS | F23: SV2 | G23: To do | H23: 3
C24: T19.3 | D24: Chống CSRF/XSS/SQL Injection | E24: • Anti-forgery token toàn bộ form POST • Mã hóa đầu ra HTML • Truy vấn tham số hóa (EF Core) | F24: SV3 | G24: To do | H24: 6
C25: T19.4 | D25: Phân quyền theo vai trò | E25: • Gắn [Authorize(Roles)] • Trang 403/404 tùy chỉnh | F25: SV5 | G25: To do | H25: 4
C26: T19.5 | D26: Kiểm thử bảo mật cơ bản | E26: • Kiểm tra HTTP→HTTPS • Thử chèn script / SQL injection | F26: SV1 | G26: To do | H26: 4
A27: US04 (5 SP) | B27: Là quản trị viên, tôi muốn xem danh sách hồ sơ gia sư chờ duyệt và duyệt hoặc từ chối kèm lý do để chỉ gia sư đạt chuẩn mới hiển thị với học viên. | C27: T04.1 | D27: Trạng thái hồ sơ gia sư | E27: • Thêm cột Status + lý do từ chối • Migration | F27: SV5 | G27: To do | H27: 3
C28: T04.2 | D28: Trang admin danh sách chờ duyệt | E28: • Bảng danh sách + bộ lọc • Trang xem chi tiết hồ sơ chờ duyệt | F28: SV4 | G28: To do | H28: 6
C29: T04.3 | D29: Chức năng duyệt / từ chối | E29: • Action duyệt • Action từ chối + validate lý do | F29: SV3 | G29: To do | H29: 5
C30: T04.4 | D30: Email kết quả duyệt | E30: • Mẫu email duyệt/từ chối • Gửi qua dịch vụ email SMTP dùng chung (đã có từ Sprint 1) | F30: SV5 | G30: To do | H30: 3
C31: T04.5 | D31: Kiểm thử duyệt hồ sơ | E31: • Test duyệt/từ chối • Test hồ sơ chưa duyệt không hiện | F31: SV1 | G31: To do | H31: 3
A32: US06 (3 SP) | B32: Là học viên, tôi muốn xem trang chi tiết hồ sơ gia sư (giới thiệu, học phí, đánh giá, lịch rảnh tóm tắt) để tôi đánh giá được gia sư trước khi đặt lịch. | C32: T06.1 | D32: Giao diện trang chi tiết gia sư | E32: • Dựng layout trang • Nút Đặt lịch | F32: SV4 | G32: To do | H32: 6
C33: T06.2 | D33: Dữ liệu đánh giá và lịch rảnh tóm tắt | E33: • Truy vấn đánh giá gần nhất • Tóm tắt khung giờ rảnh trong tuần | F33: SV3 | G33: To do | H33: 3
C34: T06.3 | D34: Kiểm thử trang chi tiết | E34: • Test hiển thị dữ liệu • Test ID không hợp lệ → 404 | F34: SV1 | G34: To do | H34: 3
G35: Tổng | H35: =SUM(H6:H34) -> 124 | I35: =SUM(I6:I34) -> 0 | J35: =IF(COUNT(J6:J34)=0,"",SUM(J6:J34)) | K35: =IF(COUNT(K6:K34)=0,"",SUM(K6:K34)) | L35: =IF(COUNT(L6:L34)=0,"",SUM(L6:L34)) | M35: =IF(COUNT(M6:M34)=0,"",SUM(M6:M34)) | N35: =IF(COUNT(N6:N34)=0,"",SUM(N6:N34)) | O35: =IF(COUNT(O6:O34)=0,"",SUM(O6:O34)) | P35: =IF(COUNT(P6:P34)=0,"",SUM(P6:P34)) | Q35: =IF(COUNT(Q6:Q34)=0,"",SUM(Q6:Q34)) | ... X35: =IF(COUNT(X6:X34)=0,"",SUM(X6:X34))
G36: Burndown lý tưởng | H36: =H35 -> 124 | J36: =$H$35-$H$35*1/15 -> 115.73333 | K36: =$H$35-$H$35*2/15 -> 107.46667 | L36: =$H$35-$H$35*3/15 -> 99.2 | M36: =$H$35-$H$35*4/15 -> 90.933333 | N36: =$H$35-$H$35*5/15 -> 82.666667 | O36: =$H$35-$H$35*6/15 -> 74.4 | P36: =$H$35-$H$35*7/15 -> 66.133333 | Q36: =$H$35-$H$35*8/15 -> 57.866667 | R36: =$H$35-$H$35*9/15 -> 49.6 | S36: =$H$35-$H$35*10/15 -> 41.333333 | T36: =$H$35-$H$35*11/15 -> 33.066667 | U36: =$H$35-$H$35*12/15 -> 24.8 | V36: =$H$35-$H$35*13/15 -> 16.533333 | W36: =$H$35-$H$35*14/15 -> 8.2666667 | X36: =$H$35-$H$35*15/15 -> 0
D38: Tải công việc theo thành viên
D39: Owner | E39: Giờ ước lượng | F39: % tổng
D40: SV1 – Product Owner | E40: =SUMIF($F$6:$F$34,"SV1",$H$6:$H$34) -> 24 | F40: =E40/$H$35 -> 0.19354839
D41: SV2 – Scrum Master | E41: =SUMIF($F$6:$F$34,"SV2",$H$6:$H$34) -> 26 | F41: =E41/$H$35 -> 0.20967742
...

Sheet Sprint backlog 2
A1: Sprint backlog 2
A2: Sprint Goal | B2: ='Sprint planning'!E14 -> Chúng ta tập trung vào học viên tìm đúng gia sư theo môn và học phí rồi đặt được buổi học vào khung giờ rảnh của gia sư, và gia sư xác nhận được yêu cầu. Chúng ta tin điều này mang lại lịch học chắc chắn, không trùng giờ và đỡ mất thời gian tìm gia sư cho học viên và gia sư. Điều này sẽ được xác nhận khi một học viên thử lọc theo môn và khoảng giá (≤ 2 giây với 500 hồ sơ mẫu) và đặt một khung giờ; hai học viên cùng đặt một khung giờ thì chỉ một người thành công; gia sư chấp nhận để booking thành "Đã xác nhận" (phát hành V1.0).
J3: Effort còn lại cuối mỗi ngày (giờ) – nhập hằng ngày
A4: UID | B4: User story (Product Backlog Item) | C4: Task ID | D4: Sprint task | E4: Subtask | F4: Owner | G4: Status | H4: Estimated effort (giờ) | I4: Actual (giờ) | J4: Day 1 | K4: Day 2 | L4: Day 3 | M4: Day 4 | N4: Day 5 | O4: Day 6 | P4: Day 7 | Q4: Day 8 | R4: Day 9 | S4: Day 10 | T4: Day 11 | U4: Day 12 | V4: Day 13 | W4: Day 14 | X4: Day 15
A5: US05 (8 SP) | B5: Là học viên, tôi muốn tìm kiếm và lọc gia sư theo môn học, mức học phí, điểm đánh giá, ngôn ngữ giảng dạy để tôi nhanh chóng chọn được gia sư phù hợp nhu cầu và ngân sách. | C5: T05.1 | D5: Truy vấn tìm kiếm và lọc | E5: • Xây dựng truy vấn LINQ động • Kết hợp nhiều bộ lọc • Sắp xếp theo giá/đánh giá | F5: SV3 | G5: To do | H5: 8
C6: T05.2 | D6: Tối ưu CSDL và phân trang | E6: • Tạo index cột tìm kiếm • Phân trang 10 bản ghi • Seed 500 hồ sơ thử | F6: SV5 | G6: To do | H6: 4
C7: T05.3 | D7: Giao diện trang tìm kiếm | E7: • Thiết kế thẻ gia sư • Sidebar bộ lọc • Trạng thái rỗng/đang tải | F7: SV4 | G7: To do | H7: 10
C8: T05.4 | D8: Gợi ý từ khóa tìm kiếm | E8: • API gợi ý • Gắn autocomplete vào ô tìm kiếm | F8: SV2 | G8: To do | H8: 3
C9: T05.5 | D9: Kiểm thử chức năng và hiệu năng | E9: • Test lọc kết hợp • Đo thời gian với 500 hồ sơ | F9: SV1 | G9: To do | H9: 4
C10: T05.6 | D10: Review code & merge | E10: • Review pull request • Merge vào develop | F10: SV2 | G10: To do | H10: 3
A11: US07 (8 SP) | B11: Là gia sư, tôi muốn thiết lập các khung giờ rảnh theo tuần (thêm, sửa, xóa) để học viên chỉ đặt vào thời điểm tôi có thể dạy. | C11: T07.1 | D11: Thiết kế CSDL lịch rảnh | E11: • ERD Availability • Entity + migration | F11: SV5 | G11: To do | H11: 4
C12: T07.2 | D12: CRUD khung giờ rảnh + chống chồng lấn | E12: • Action thêm/sửa/xóa • Kiểm tra chồng lấn • Chặn sửa/xóa khung đã đặt | F12: SV3 | G12: To do | H12: 8
C13: T07.3 | D13: Giao diện lịch tuần của gia sư | E13: • Tích hợp thư viện lịch • Form thêm/sửa khung giờ • Hiển thị khung đã đặt khác màu | F13: SV4 | G13: To do | H13: 10
C14: T07.4 | D14: Xử lý múi giờ và định dạng | E14: • Chuẩn hóa lưu UTC • Chuyển đổi khi hiển thị | F14: SV5 | G14: To do | H14: 3
C15: T07.5 | D15: Kiểm thử lịch rảnh | E15: • Test chồng lấn • Test khung giờ quá khứ | F15: SV1 | G15: To do | H15: 4
C16: T07.6 | D16: Review code và chuẩn bị demo Sprint 2 | E16: • Review pull request • Chuẩn bị dữ liệu demo | F16: SV2 | G16: To do | H16: 3
A17: US08 (8 SP) | B17: Là học viên, tôi muốn chọn một khung giờ trống của gia sư và xác nhận đặt buổi học để tôi có buổi học đúng thời điểm mình mong muốn. | C17: T08.1 | D17: Thiết kế CSDL đặt lịch | E17: • ERD Booking • Entity + migration • Enum trạng thái | F17: SV5 | G17: To do | H17: 4
C18: T08.2 | D18: Logic đặt lịch và chống đặt trùng | E18: • Kiểm tra slot còn trống • Dùng RowVersion/transaction • Trả lỗi thân thiện khi slot vừa bị đặt | F18: SV2 | G18: To do | H18: 10
C19: T08.3 | D19: Giao diện chọn khung giờ và xác nhận | E19: • Chọn khung giờ • Màn hình xác nhận • Thông báo kết quả | F19: SV1 | G19: To do | H19: 8
C20: T08.4 | D20: Email thông báo yêu cầu cho gia sư | E20: • Mẫu email yêu cầu đặt lịch • Gửi qua dịch vụ email SMTP dùng chung | F20: SV5 | G20: To do | H20: 3
C21: T08.5 | D21: Kiểm thử đặt lịch, kể cả đồng thời | E21: • Test 2 người đặt cùng slot • Test slot quá khứ | F21: SV1 | G21: To do | H21: 4
C22: T08.6 | D22: Review code & merge | E22: • Review pull request • Merge vào develop | F22: SV2 | G22: To do | H22: 3
A23: US09 (5 SP) | B23: Là gia sư, tôi muốn chấp nhận hoặc từ chối yêu cầu đặt lịch của học viên để tôi chủ động sắp xếp lịch dạy của mình. | C23: T09.1 | D23: Giao diện danh sách yêu cầu của gia sư | E23: • Bảng yêu cầu • Nút chấp nhận/từ chối | F23: SV4 | G23: To do | H23: 5
C24: T09.2 | D24: Chấp nhận / từ chối và cập nhật trạng thái | E24: • Action chấp nhận • Action từ chối, mở lại slot • Gửi email kết quả cho học viên | F24: SV3 | G24: To do | H24: 6
C25: T09.3 | D25: Tự hủy yêu cầu quá 24 giờ | E25: • HostedService quét định kỳ • Hủy booking và mở lại slot | F25: SV5 | G25: To do | H25: 5
C26: T09.4 | D26: Kiểm thử xác nhận/từ chối | E26: • Test chấp nhận/từ chối • Test tự hủy | F26: SV1 | G26: To do | H26: 4
G27: Tổng | H27: =SUM(H5:H26) -> 116 | I27: =SUM(I5:I26) -> 0 | J27: =IF(COUNT(J5:J26)=0,"",SUM(J5:J26)) | K27: =IF(COUNT(K5:K26)=0,"",SUM(K5:K26)) | L27: =IF(COUNT(L5:L26)=0,"",SUM(L5:L26)) | M27: =IF(COUNT(M5:M26)=0,"",SUM(M5:M26)) | N27: =IF(COUNT(N5:N26)=0,"",SUM(N5:N26)) | O27: =IF(COUNT(O5:O26)=0,"",SUM(O5:O26)) | P27: =IF(COUNT(P5:P26)=0,"",SUM(P5:P26)) | Q27: =IF(COUNT(Q5:Q26)=0,"",SUM(Q5:Q26)) | ... X27: =IF(COUNT(X5:X26)=0,"",SUM(X5:X26))
G28: Burndown lý tưởng | H28: =H27 -> 116 | J28: =$H$27-$H$27*1/15 -> 108.26667 | K28: =$H$27-$H$27*2/15 -> 100.53333 | L28: =$H$27-$H$27*3/15 -> 92.8 | M28: =$H$27-$H$27*4/15 -> 85.066667 | N28: =$H$27-$H$27*5/15 -> 77.333333 | O28: =$H$27-$H$27*6/15 -> 69.6 | P28: =$H$27-$H$27*7/15 -> 61.866667 | Q28: =$H$27-$H$27*8/15 -> 54.133333 | R28: =$H$27-$H$27*9/15 -> 46.4 | S28: =$H$27-$H$27*10/15 -> 38.666667 | T28: =$H$27-$H$27*11/15 -> 30.933333 | U28: =$H$27-$H$27*12/15 -> 23.2 | V28: =$H$27-$H$27*13/15 -> 15.466667 | W28: =$H$27-$H$27*14/15 -> 7.7333333 | X28: =$H$27-$H$27*15/15 -> 0
D30: Tải công việc theo thành viên
D31: Owner | E31: Giờ ước lượng | F31: % tổng
D32: SV1 – Product Owner | E32: =SUMIF($F$5:$F$26,"SV1",$H$5:$H$26) -> 24 | F32: =E32/$H$27 -> 0.20689655
D33: SV2 – Scrum Master | E33: =SUMIF($F$5:$F$26,"SV2",$H$5:$H$26) -> 22 | F33: =E33/$H$27 -> 0.18965517
D34: SV3 – Developer | E34: =SUMIF($F$5:$F$26,"SV3",$H$5:$H$26) -> 22 | F34: =E34/$H$27 -> 0.18965517
D35: SV4 – Developer | E35: =SUMIF($F$5:$F$26,"SV4",$H$5:$H$26) -> 25 | F35: =E35/$H$27 -> 0.21551724
D36: SV5 – Developer | E36: =SUMIF($F$5:$F$26,"SV5",$H$5:$H$26) -> 23 | F36: =E36/$H$27 -> 0.19827586

Sheet Sprint backlog 3
A1: Sprint backlog 3
A2: Sprint Goal | B2: ='Sprint planning'!E15 -> Chúng ta tập trung vào học viên thanh toán online và vào học video ngay trên web, và bản V2.0 sẵn sàng cho người dùng thật. Chúng ta tin điều này mang lại khả năng giữ chỗ buổi học không cần tiền mặt và học không phải cài thêm phần mềm cho học viên và gia sư. Điều này sẽ được xác nhận khi ≥ 5 người dùng thử hoàn thành trọn luồng đăng ký → tìm → đặt → thanh toán → vào cùng phòng học đúng giờ trên bản chạy HTTPS .
J4: Effort còn lại cuối mỗi ngày (giờ) – nhập hằng ngày
A5: UID | B5: User story (Product Backlog Item) | C5: Task ID | D5: Sprint task | E5: Subtask | F5: Owner | G5: Status | H5: Estimated effort (giờ) | I5: Actual (giờ) | J5: Day 1 | K5: Day 2 | L5: Day 3 | M5: Day 4 | N5: Day 5 | O5: Day 6 | P5: Day 7 | Q5: Day 8 | R5: Day 9 | S5: Day 10 | T5: Day 11 | U5: Day 12 | V5: Day 13 | W5: Day 14 | X5: Day 15
I6: Ngày | J6: =WORKDAY(#REF!,0,'Sprint planning'!$B$8) -> #REF! | K6: =WORKDAY(#REF!,1,'Sprint planning'!$B$8) -> #REF! | L6: =WORKDAY(#REF!,2,'Sprint planning'!$B$8) -> #REF! | M6: =WORKDAY(#REF!,3,'Sprint planning'!$B$8) -> #REF! | N6: =WORKDAY(#REF!,4,'Sprint planning'!$B$8) -> #REF! | O6: =WORKDAY(#REF!,5,'Sprint planning'!$B$8) -> #REF! | P6: =WORKDAY(#REF!,6,'Sprint planning'!$B$8) -> #REF! | Q6: =WORKDAY(#REF!,7,'Sprint planning'!$B$8) -> #REF! | R6: =WORKDAY(#REF!,8,'Sprint planning'!$B$8) -> #REF! | S6: =WORKDAY(#REF!,9,'Sprint planning'!$B$8) -> #REF! | T6: =WORKDAY(#REF!,10,'Sprint planning'!$B$8) -> #REF! | U6: =WORKDAY(#REF!,11,'Sprint planning'!$B$8) -> #REF! | V6: =WORKDAY(#REF!,12,'Sprint planning'!$B$8) -> #REF! | W6: =WORKDAY(#REF!,13,'Sprint planning'!$B$8) -> #REF! | X6: =WORKDAY(#REF!,14,'Sprint planning'!$B$8) -> #REF!
A7: US12 (13 SP) | B7: Là học viên, tôi muốn thanh toán học phí online (thẻ ATM/ví điện tử qua cổng sandbox) khi đặt lịch để tôi giữ chỗ buổi học và không phải trả tiền mặt. | C7: T12.1 | D7: Nghiên cứu cổng thanh toán sandbox | E7: • Đọc tài liệu API • Đăng ký tài khoản sandbox • Chốt phương án + ghi tài liệu | F7: SV2 | G7: To do | H7: 5
C8: T12.2 | D8: Thiết kế CSDL thanh toán | E8: • ERD Payment • Entity + migration • Ràng buộc duy nhất mã giao dịch | F8: SV5 | G8: To do | H8: 4
C9: T12.3 | D9: Tạo yêu cầu thanh toán | E9: • Dựng tham số và chữ ký • Tạo bản ghi giao dịch Pending • Chuyển hướng sang cổng | F9: SV3 | G9: To do | H9: 10
C10: T12.4 | D10: Xử lý callback/IPN và xác thực chữ ký | E10: • Endpoint nhận callback • Xác thực chữ ký • Cập nhật booking một lần (idempotent) | F10: SV1 | G10: To do | H10: 8
C11: T12.5 | D11: Giao diện thanh toán và trang kết quả | E11: • Trang tóm tắt đơn • Trang kết quả + biên lai • Nút thử lại | F11: SV4 | G11: To do | H11: 8
C12: T12.6 | D12: Xử lý lỗi, timeout, thanh toán lặp | E12: • Hết hạn giao dịch Pending • Chặn thanh toán lặp • Ghi log lỗi | F12: SV5 | G12: To do | H12: 6
C13: T12.7 | D13: Kiểm thử trên sandbox | E13: • Test thành công/thất bại • Test callback giả mạo/trùng | F13: SV1 | G13: To do | H13: 6
C14: T12.8 | D14: Bảo mật thông tin thanh toán | E14: • Lưu khóa bí mật trong User Secrets/biến môi trường • Không ghi dữ liệu nhạy cảm vào log | F14: SV2 | G14: To do | H14: 5
A15: US14 (8 SP) | B15: Là học viên / gia sư, tôi muốn vào phòng học video riêng của buổi học bằng một nút bấm để chúng tôi học trực tuyến mà không cần cài thêm phần mềm. | C15: T14.1 | D15: Chọn giải pháp video | E15: • Thử nghiệm Jitsi iFrame API • Chốt phương án + ghi tài liệu | F15: SV2 | G15: To do | H15: 4
C16: T14.2 | D16: Sinh phòng học duy nhất theo booking | E16: • Sinh mã phòng ngẫu nhiên • Lưu mã phòng vào booking | F16: SV3 | G16: To do | H16: 8
C17: T14.3 | D17: Kiểm soát quyền vào phòng | E17: • Kiểm tra người dùng thuộc booking • Kiểm tra cửa sổ thời gian | F17: SV5 | G17: To do | H17: 6
C18: T14.4 | D18: Giao diện phòng học nhúng | E18: • Nhúng video • Đồng hồ đếm giờ buổi học • Nút rời phòng | F18: SV4 | G18: To do | H18: 8
C19: T14.5 | D19: Kiểm thử đa trình duyệt | E19: • Test Chrome/Edge/Firefox • Test truy cập trái phép | F19: SV1 | G19: To do | H19: 4
C20: T14.6 | D20: Ghi nhận hoàn thành buổi học | E20: • Chuyển Completed khi hết giờ • Ghi thời lượng thực tế | F20: SV3 | G20: To do | H20: 2
A21: US20 (8 SP) | B21: Là nhóm phát triển, tôi muốn kiểm thử tích hợp/hồi quy, UAT, triển khai và hoàn thiện tài liệu hướng dẫn để sản phẩm ổn định, đáp ứng Definition of Done và sẵn sàng bàn giao. | C21: T20.1 | D21: Kiểm thử tích hợp và hồi quy | E21: • Lập checklist hồi quy • Chạy và ghi nhận lỗi | F21: SV1 | G21: To do | H21: 8
C22: T20.2 | D22: UAT với người dùng thử | E22: • Chuẩn bị kịch bản UAT • Thu phản hồi + biên bản | F22: SV2 | G22: To do | H22: 6
C23: T20.3 | D23: Sửa lỗi từ kiểm thử/UAT | E23: • Phân loại lỗi • Sửa và kiểm tra lại | F23: SV3 | G23: To do | H23: 6
C24: T20.4 | D24: Triển khai | E24: • Cấu hình Kestrel/IIS + SQL Server • Cài chứng chỉ HTTPS • Kiểm thử sau triển khai | F24: SV5 | G24: To do | H24: 5
C25: T20.5 | D25: Hướng dẫn sử dụng và báo cáo BTL | E25: • Hướng dẫn cho học viên/gia sư/admin • Hoàn thiện báo cáo BTL | F25: SV2 | G25: To do | H25: 4
C26: T20.6 | D26: Tinh chỉnh giao diện và hiệu năng | E26: • Rà soát UI/UX • Tối ưu truy vấn chậm | F26: SV4 | G26: To do | H26: 3
G27: Tổng | H27: =SUM(H7:H26) -> 116 | I27: =SUM(I7:I26) -> 0 | J27: =IF(COUNT(J7:J26)=0,"",SUM(J7:J26)) | K27: =IF(COUNT(K7:K26)=0,"",SUM(K7:K26)) | L27: =IF(COUNT(L7:L26)=0,"",SUM(L7:L26)) | M27: =IF(COUNT(M7:M26)=0,"",SUM(M7:M26)) | N27: =IF(COUNT(N7:N26)=0,"",SUM(N7:N26)) | O27: =IF(COUNT(O7:O26)=0,"",SUM(O7:O26)) | P27: =IF(COUNT(P7:P26)=0,"",SUM(P7:P26)) | Q27: =IF(COUNT(Q7:Q26)=0,"",SUM(Q7:Q26)) | ... X27: =IF(COUNT(X7:X26)=0,"",SUM(X7:X26))
G28: Burndown lý tưởng | H28: =H27 -> 116 | J28: =$H$27-$H$27*1/15 -> 108.26667 | K28: =$H$27-$H$27*2/15 -> 100.53333 | L28: =$H$27-$H$27*3/15 -> 92.8 | M28: =$H$27-$H$27*4/15 -> 85.066667 | N28: =$H$27-$H$27*5/15 -> 77.333333 | O28: =$H$27-$H$27*6/15 -> 69.6 | P28: =$H$27-$H$27*7/15 -> 61.866667 | Q28: =$H$27-$H$27*8/15 -> 54.133333 | R28: =$H$27-$H$27*9/15 -> 46.4 | S28: =$H$27-$H$27*10/15 -> 38.666667 | T28: =$H$27-$H$27*11/15 -> 30.933333 | U28: =$H$27-$H$27*12/15 -> 23.2 | V28: =$H$27-$H$27*13/15 -> 15.466667 | W28: =$H$27-$H$27*14/15 -> 7.7333333 | X28: =$H$27-$H$27*15/15 -> 0
D30: Tải công việc theo thành viên
D31: Owner | E31: Giờ ước lượng | F31: % tổng
D32: SV1 – Product Owner | E32: =SUMIF($F$7:$F$26,"SV1",$H$7:$H$26) -> 26 | F32: =E32/$H$27 -> 0.22413793
D33: SV2 – Scrum Master | E33: =SUMIF($F$7:$F$26,"SV2",$H$7:$H$26) -> 24 | F33: =E33/$H$27 -> 0.20689655
D34: SV3 – Developer | E34: =SUMIF($F$7:$F$26,"SV3",$H$7:$H$26) -> 26 | F34: =E34/$H$27 -> 0.22413793
D35: SV4 – Developer | E35: =SUMIF($F$7:$F$26,"SV4",$H$7:$H$26) -> 19 | F35: =E35/$H$27 -> 0.1637931
D36: SV5 – Developer | E36: =SUMIF($F$7:$F$26,"SV5",$H$7:$H$26) -> 21 | F36: =E36/$H$27 -> 0.18103448

Sheet US_Task
A1: US – TASK – SUBTASK (danh mục công việc theo User Story)
A2: Mỗi User Story chia thành Task; mỗi Task chia thành Subtask. Số giờ mỗi story = Story Point × giờ/SP.
A3: User Story | B3: Task | C3: Mô tả chi tiết (CoS) | D3: Subtask | E3: Người | F3: Ước lượng thời gian (giờ) | G3: Số giờ thực tế | H3: Sprint
A4: US01 (5 SP) Là học viên / gia sư, tôi muốn đăng ký tài khoản bằng email và mật khẩu để tôi có thể sử dụng hệ thống theo đúng vai trò của mình. | B4: T01.1 Thiết kế CSDL người dùng | C4: Bảng Users/Roles và quan hệ. | D4: • Vẽ ERD Users–Roles • Tạo entity + migration EF Core • Seed 3 vai trò Student/Tutor/Admin | E4: SV5 | F4: 3 | H4: 1
B5: T01.2 Xử lý đăng ký (Controller/Service) | C5: Nhận form, kiểm tra và tạo tài khoản. | D5: • Validate dữ liệu (email, mật khẩu) • Băm mật khẩu bằng ASP.NET Core Identity • Cấu hình dịch vụ email SMTP dùng chung + gửi email xác nhận | E5: SV1 | F5: 6 | H5: 1
B6: T01.3 Giao diện đăng ký | C6: Form đăng ký chọn vai trò. | D6: • Dựng form Razor + Bootstrap • Hiển thị lỗi validate • Responsive mobile | E6: SV4 | F6: 6 | H6: 1
B7: T01.4 Kiểm thử đăng ký | C7: Chạy test case TC01–TC05. | D7: • Viết test case • Test trùng email / mật khẩu yếu | E7: SV1 | F7: 3 | H7: 1
B8: T01.5 Review code & merge | C8: Review PR, gộp vào nhánh develop. | D8: • Review pull request • Merge và kiểm tra build | E8: SV2 | F8: 2 | H8: 1
A9: US02 (5 SP) Là người dùng, tôi muốn đăng nhập, đăng xuất và đặt lại mật khẩu khi quên để tôi truy cập được tài khoản an toàn và lấy lại quyền truy cập khi quên mật khẩu. | B9: T02.1 Đăng nhập / đăng xuất | C9: Xác thực cookie, khóa tài khoản khi sai nhiều lần. | D9: • Action đăng nhập • Khóa 15 phút sau 5 lần sai • Action đăng xuất | E9: SV3 | F9: 6 | H9: 1
B10: T02.2 Quên / đặt lại mật khẩu | C10: Luồng token qua email. | D10: • Sinh token có hạn 30 phút • Gửi email đặt lại • Trang đặt lại mật khẩu | E10: SV3 | F10: 5 | H10: 1
B11: T02.3 Giao diện đăng nhập & quên mật khẩu | C11: Các trang xác thực. | D11: • Trang đăng nhập • Trang quên/đặt lại mật khẩu • Thông báo lỗi/thành công | E11: SV4 | F11: 5 | H11: 1
B12: T02.4 Kiểm thử đăng nhập | C12: Chạy test case TC01–TC05. | D12: • Test đăng nhập đúng/sai • Test token hết hạn/dùng lại | E12: SV1 | F12: 2 | H12: 1
B13: T02.5 Review code & merge | C13: Review PR. | D13: • Review pull request • Merge vào develop | E13: SV2 | F13: 2 | H13: 1
A14: US03 (8 SP) Là gia sư, tôi muốn tạo và cập nhật hồ sơ (ảnh, giới thiệu, môn dạy, học phí/giờ, kinh nghiệm, chứng chỉ) để học viên hiểu rõ năng lực của tôi và chọn tôi. | B14: T03.1 Thiết kế CSDL hồ sơ gia sư | C14: Bảng TutorProfile, Subject, TutorSubject, Certificate. | D14: • Vẽ ERD hồ sơ • Entity + migration • Seed danh sách môn học | E14: SV5 | F14: 5 | H14: 1
B15: T03.2 CRUD hồ sơ gia sư | C15: Tạo, xem, sửa hồ sơ. | D15: • Action Create/Edit • Validate học phí, trường bắt buộc • Chuyển trạng thái Chờ duyệt khi lưu | E15: SV2 | F15: 8 | H15: 1
B16: T03.3 Upload ảnh và chứng chỉ | C16: Lưu file an toàn. | D16: • Giới hạn định dạng JPG/PNG/PDF • Giới hạn 5 MB, đổi tên file ngẫu nhiên • Lưu ngoài thư mục wwwroot công khai (chứng chỉ) | E16: SV5 | F16: 5 | H16: 1
B17: T03.4 Giao diện form hồ sơ nhiều bước | C17: Form 3 bước: cơ bản – chuyên môn – chứng chỉ. | D17: • Dựng stepper • Kiểm tra dữ liệu phía client • Xem trước ảnh đại diện | E17: SV2 | F17: 8 | H17: 1
B18: T03.5 Trang xem hồ sơ cá nhân | C18: Gia sư xem hồ sơ như học viên thấy. | D18: • Dựng trang xem • Hiển thị trạng thái duyệt | E18: SV4 | F18: 3 | H18: 1
B19: T03.6 Kiểm thử hồ sơ gia sư | C19: Chạy test case TC01–TC05. | D19: • Test upload sai định dạng/dung lượng • Test sửa hồ sơ đã duyệt | E19: SV1 | F19: 3 | H19: 1
A20: US19 (5 SP) Là người dùng, tôi muốn dữ liệu của tôi được bảo vệ bằng HTTPS, phân quyền và chống các tấn công phổ biến để thông tin cá nhân và giao dịch không bị lộ hoặc bị giả mạo. | B20: T19.1 Thiết lập repo Git, quy ước nhánh, bảng công việc | C20: Môi trường làm việc nhóm. | D20: • Tạo repo, nhánh main/develop/feature • Quy ước commit + PR • Tạo board Scrum (Trello/Jira) | E20: SV2 | F20: 3 | H20: 1
B21: T19.2 Cấu hình HTTPS/HSTS | C21: Chứng chỉ dev và chuyển hướng. | D21: • Chứng chỉ phát triển Kestrel • Bắt buộc chuyển hướng HTTPS • Bật HSTS | E21: SV2 | F21: 3 | H21: 1
B22: T19.3 Chống CSRF/XSS/SQL Injection | C22: Bảo vệ các form và truy vấn. | D22: • Anti-forgery token toàn bộ form POST • Mã hóa đầu ra HTML • Truy vấn tham số hóa (EF Core) | E22: SV3 | F22: 6 | H22: 1
B23: T19.4 Phân quyền theo vai trò | C23: Authorize theo role/policy. | D23: • Gắn [Authorize(Roles)] • Trang 403/404 tùy chỉnh | E23: SV5 | F23: 4 | H23: 1
B24: T19.5 Kiểm thử bảo mật cơ bản | C24: Chạy test case TC01–TC05. | D24: • Kiểm tra HTTP→HTTPS • Thử chèn script / SQL injection | E24: SV1 | F24: 4 | H24: 1
A25: US04 (5 SP) Là quản trị viên, tôi muốn xem danh sách hồ sơ gia sư chờ duyệt và duyệt hoặc từ chối kèm lý do để chỉ gia sư đạt chuẩn mới hiển thị với học viên. | B25: T04.1 Trạng thái hồ sơ gia sư | C25: Pending/Approved/Rejected. | D25: • Thêm cột Status + lý do từ chối • Migration | E25: SV5 | F25: 3 | H25: 1
B26: T04.2 Trang admin danh sách chờ duyệt | C26: Giao diện cho admin. | D26: • Bảng danh sách + bộ lọc • Trang xem chi tiết hồ sơ chờ duyệt | E26: SV4 | F26: 6 | H26: 1
B27: T04.3 Chức năng duyệt / từ chối | C27: Cập nhật trạng thái, bắt buộc lý do khi từ chối. | D27: • Action duyệt • Action từ chối + validate lý do | E27: SV3 | F27: 5 | H27: 1
B28: T04.4 Email kết quả duyệt | C28: Thông báo cho gia sư. | D28: • Mẫu email duyệt/từ chối • Gửi qua dịch vụ email SMTP dùng chung (đã có từ Sprint 1) | E28: SV5 | F28: 3 | H28: 1
B29: T04.5 Kiểm thử duyệt hồ sơ | C29: Chạy test case TC01–TC04. | D29: • Test duyệt/từ chối • Test hồ sơ chưa duyệt không hiện | E29: SV1 | F29: 3 | H29: 1
A30: US06 (3 SP) Là học viên, tôi muốn xem trang chi tiết hồ sơ gia sư (giới thiệu, học phí, đánh giá, lịch rảnh tóm tắt) để tôi đánh giá được gia sư trước khi đặt lịch. | B30: T06.1 Giao diện trang chi tiết gia sư | C30: Hiển thị hồ sơ đầy đủ. | D30: • Dựng layout trang • Nút Đặt lịch | E30: SV4 | F30: 6 | H30: 1
B31: T06.2 Dữ liệu đánh giá và lịch rảnh tóm tắt | C31: Truy vấn dữ liệu phụ. | D31: • Truy vấn đánh giá gần nhất • Tóm tắt khung giờ rảnh trong tuần | E31: SV3 | F31: 3 | H31: 1
B32: T06.3 Kiểm thử trang chi tiết | C32: Chạy test case TC01–TC03. | D32: • Test hiển thị dữ liệu • Test ID không hợp lệ → 404 | E32: SV1 | F32: 3 | H32: 1
A33: US05 (8 SP) Là học viên, tôi muốn tìm kiếm và lọc gia sư theo môn học, mức học phí, điểm đánh giá, ngôn ngữ giảng dạy để tôi nhanh chóng chọn được gia sư phù hợp nhu cầu và ngân sách. | B33: T05.1 Truy vấn tìm kiếm và lọc | C33: Lọc theo môn, giá, điểm, ngôn ngữ. | D33: • Xây dựng truy vấn LINQ động • Kết hợp nhiều bộ lọc • Sắp xếp theo giá/đánh giá | E33: SV3 | F33: 8 | H33: 2
B34: T05.2 Tối ưu CSDL và phân trang | C34: Chỉ mục và phân trang. | D34: • Tạo index cột tìm kiếm • Phân trang 10 bản ghi • Seed 500 hồ sơ thử | E34: SV5 | F34: 4 | H34: 2
B35: T05.3 Giao diện trang tìm kiếm | C35: Danh sách thẻ gia sư + sidebar bộ lọc. | D35: • Thiết kế thẻ gia sư • Sidebar bộ lọc • Trạng thái rỗng/đang tải | E35: SV4 | F35: 10 | H35: 2
B36: T05.4 Gợi ý từ khóa tìm kiếm | C36: Autocomplete tên môn. | D36: • API gợi ý • Gắn autocomplete vào ô tìm kiếm | E36: SV2 | F36: 3 | H36: 2
B37: T05.5 Kiểm thử chức năng và hiệu năng | C37: Chạy test case TC01–TC05. | D37: • Test lọc kết hợp • Đo thời gian với 500 hồ sơ | E37: SV1 | F37: 4 | H37: 2
B38: T05.6 Review code & merge | C38: Review PR. | D38: • Review pull request • Merge vào develop | E38: SV2 | F38: 3 | H38: 2
A39: US07 (8 SP) Là gia sư, tôi muốn thiết lập các khung giờ rảnh theo tuần (thêm, sửa, xóa) để học viên chỉ đặt vào thời điểm tôi có thể dạy. | B39: T07.1 Thiết kế CSDL lịch rảnh | C39: Bảng Availability. | D39: • ERD Availability • Entity + migration | E39: SV5 | F39: 4 | H39: 2
B40: T07.2 CRUD khung giờ rảnh + chống chồng lấn | C40: Logic nghiệp vụ lịch. | D40: • Action thêm/sửa/xóa • Kiểm tra chồng lấn • Chặn sửa/xóa khung đã đặt | E40: SV3 | F40: 8 | H40: 2
...

Sheet Sprint Review
A1: SPRINT REVIEW
A2: Mục tiêu: trình bày kết quả của Sprint (demo phần mềm chạy được) và thu thập phản hồi để cập nhật Product Backlog
A3: Vai trò | B3: Nhiệm vụ trong buổi Review
A4: Product Owner (SV1) | B4: Giải thích Sprint Goal; nêu story Done / chưa Done; bàn việc tiếp theo của Product Backlog; mời người dùng thử/giảng viên phản hồi.
A5: Dev Team (SV3–SV5) | B5: Demo phần đã hoàn thành theo Definition of Done; trả lời câu hỏi; nêu vấn đề và rủi ro gặp phải.
A6: Scrum Master (SV2) | B6: Đảm bảo sự kiện diễn ra đúng giờ, có cấu trúc, tạo môi trường góp ý cởi mở; ghi biên bản.
A7: Stakeholder (giảng viên/người dùng thử) | B7: Đưa phản hồi về sản phẩm và Sprint; chất vấn PO về tiến độ và định hướng tiếp theo.
A9: Tên sprint (Sprint title): | B9: Sprint 1
A10: Mục tiêu (Sprint goal): | B10: ='Sprint planning'!E13 -> Chúng ta tập trung vào gia sư đăng ký, đưa hồ sơ chuyên môn lên hệ thống và được admin kiểm duyệt để hồ sơ hiển thị công khai. Chúng ta tin điều này mang lại một kênh tự giới thiệu năng lực và sự tin cậy nhờ được kiểm duyệt cho gia sư và học viên. Điều này sẽ được xác nhận khi một gia sư thử nghiệm đăng ký, đăng nhập, điền xong hồ sơ; admin duyệt; rồi người chưa đăng nhập mở được trang chi tiết hồ sơ đã duyệt (hồ sơ chưa duyệt trả về 404).
A11: Từ ngày (From): | B11: ='Sprint planning'!B13 -> 46321 | C11: đến ngày (To): | D11: ='Sprint planning'!C13 -> 46339
A12: Team / Người demo | B12: Role | C12: Sprint status (User Story) | D12: Things to demo (task demo) | E12: Quick update (phản hồi và cập nhật mới) | F12: Điều chỉnh (what next) | G12: Trạng thái
A13: Nhóm 8 – SV5 | B13: Developer | C13: US01: Là học viên / gia sư, tôi muốn đăng ký tài khoản bằng email và mật khẩu để tôi có thể sử dụng hệ thống theo đúng vai trò của mình. | D13: • Thiết kế CSDL người dùng • Xử lý đăng ký (Controller/Service) • Giao diện đăng ký | G13: To do
A14: Nhóm 8 – SV3 | B14: Developer | C14: US02: Là người dùng, tôi muốn đăng nhập, đăng xuất và đặt lại mật khẩu khi quên để tôi truy cập được tài khoản an toàn và lấy lại quyền truy cập khi quên mật khẩu. | D14: • Đăng nhập / đăng xuất • Quên / đặt lại mật khẩu • Giao diện đăng nhập & quên mật khẩu | G14: To do
A15: Nhóm 8 – SV5 | B15: Developer | C15: US03: Là gia sư, tôi muốn tạo và cập nhật hồ sơ (ảnh, giới thiệu, môn dạy, học phí/giờ, kinh nghiệm, chứng chỉ) để học viên hiểu rõ năng lực của tôi và chọn tôi. | D15: • Thiết kế CSDL hồ sơ gia sư • CRUD hồ sơ gia sư • Upload ảnh và chứng chỉ • Giao diện form hồ sơ nhiều bước | G15: To do
A16: Nhóm 8 – SV2 | B16: Scrum Master | C16: US19: Là người dùng, tôi muốn dữ liệu của tôi được bảo vệ bằng HTTPS, phân quyền và chống các tấn công phổ biến để thông tin cá nhân và giao dịch không bị lộ hoặc bị giả mạo. | D16: • Thiết lập repo Git, quy ước nhánh, bảng công việc • Cấu hình HTTPS/HSTS • Chống CSRF/XSS/SQL Injection • Phân quyền theo vai trò | G16: To do
